# Issue 2022-08-16

The command outputs:

```log
Environment information:
System: Linux 5.15.0-25-generic
Current Version: pytorchyolo 1.6.2
Current Commit Hash: 66ad089
Command line arguments: Namespace(checkpoint_interval=1, conf_thres=0.1, data='config/person-yolov3-tiny.data', epochs=100, evaluation_interval=1, iou_thres=0.5, logdir='logs', model='config/person-yolov3-tiny.cfg', multiscale_training=False, n_cpu=8, nms_thres=0.5, pretrained_weights='weights/yolov3-tiny.weights', seed=-1, verbose=False)

Traceback (most recent call last):
  File "<string>", line 1, in <module>
  File "/home/x/actions-runner/_work/pytorch-yolov3-helloworld/pytorch-yolov3-helloworld/pytorchyolo/train.py", line 118, in run
    args.multiscale_training)
  File "/home/x/actions-runner/_work/pytorch-yolov3-helloworld/pytorch-yolov3-helloworld/pytorchyolo/train.py", line 48, in _create_data_loader
    transform=AUGMENTATION_TRANSFORMS)
  File "/home/x/actions-runner/_work/pytorch-yolov3-helloworld/pytorch-yolov3-helloworld/pytorchyolo/utils/datasets.py", line 68, in __init__
    f"Image path must contain a folder named 'images'! \n'{image_dir}'"
AssertionError: Image path must contain a folder named 'images'!
```

The command used to train is:

```
pythonLocation=/home/x/actions-runner/_work/_tool/Python/3.7.13/x64 PKG_CONFIG_PATH=/home/x/actions-runner/_work/_tool/Python/3.7.13/x64/lib/pkgconfig Python_ROOT_DIR=/home/x/actions-runner/_work/_tool/Python/3.7.13/x64 Python2_ROOT_DIR=/home/x/actions-runner/_work/_tool/Python/3.7.13/x64 Python3_ROOT_DIR=/home/x/actions-runner/_work/_tool/Python/3.7.13/x64 LD_LIBRARY_PATH=/home/x/actions-runner/_work/_tool/Python/3.7.13/x64/lib $HOME/.local/bin/poetry run yolo-train --n_cpu 8 --epochs 100 --data config/person-yolov3-tiny.data --model config/person-yolov3-tiny.cfg --pretrained_weights weights/yolov3-tiny.weights
```

## Analysis

The issue was in `datasets.py` file, line 67.

Had to change this line today.
